2024-03-14 17:41:45,290 INFO    StreamThr :175919 [internal.py:wandb_internal():89] W&B internal server running at pid: 175919, started at: 2024-03-14 17:41:45.288890
2024-03-14 17:41:45,294 DEBUG   HandlerThread:175919 [handler.py:handle_request():146] handle_request: status
2024-03-14 17:41:45,299 INFO    WriterThread:175919 [datastore.py:open_for_write():87] open: /data/lujunda/baidu/duomo/data/leftdata/clipscore/cloth-matvh/wandb/run-20240314_174145-bk7j44wm/run-bk7j44wm.wandb
2024-03-14 17:41:45,300 DEBUG   SenderThread:175919 [sender.py:send():378] send: header
2024-03-14 17:41:45,300 DEBUG   SenderThread:175919 [sender.py:send():378] send: run
2024-03-14 17:41:45,891 ERROR   SenderThread:175919 [internal_api.py:execute():373] 404 response executing GraphQL.
2024-03-14 17:41:45,891 ERROR   SenderThread:175919 [internal_api.py:execute():374] {"errors":[{"message":"entity your_username not found during upsertBucket","path":["upsertBucket"]}],"data":{"upsertBucket":null}}
2024-03-14 17:41:45,891 ERROR   SenderThread:175919 [sender.py:send_run():950] It appears that you do not have permission to access the requested resource. Please reach out to the project owner to grant you access. If you have the correct permissions, verify that there are no issues with your networking setup.(Error 404: Not Found)
Traceback (most recent call last):
  File "/home/lujunda/.conda/envs/myyolov5/lib/python3.7/site-packages/wandb/sdk/lib/retry.py", line 131, in __call__
    result = self._call_fn(*args, **kwargs)
  File "/home/lujunda/.conda/envs/myyolov5/lib/python3.7/site-packages/wandb/sdk/internal/internal_api.py", line 369, in execute
    return self.client.execute(*args, **kwargs)  # type: ignore
  File "/home/lujunda/.conda/envs/myyolov5/lib/python3.7/site-packages/wandb/vendor/gql-0.2.0/wandb_gql/client.py", line 52, in execute
    result = self._get_result(document, *args, **kwargs)
  File "/home/lujunda/.conda/envs/myyolov5/lib/python3.7/site-packages/wandb/vendor/gql-0.2.0/wandb_gql/client.py", line 60, in _get_result
    return self.transport.execute(document, *args, **kwargs)
  File "/home/lujunda/.conda/envs/myyolov5/lib/python3.7/site-packages/wandb/sdk/lib/gql_request.py", line 59, in execute
    request.raise_for_status()
  File "/home/lujunda/.conda/envs/myyolov5/lib/python3.7/site-packages/requests/models.py", line 1021, in raise_for_status
    raise HTTPError(http_error_msg, response=self)
requests.exceptions.HTTPError: 404 Client Error: Not Found for url: https://api.wandb.ai/graphql

During handling of the above exception, another exception occurred:

Traceback (most recent call last):
  File "/home/lujunda/.conda/envs/myyolov5/lib/python3.7/site-packages/wandb/sdk/internal/sender.py", line 948, in send_run
    self._init_run(run, config_value_dict)
  File "/home/lujunda/.conda/envs/myyolov5/lib/python3.7/site-packages/wandb/sdk/internal/sender.py", line 1004, in _init_run
    commit=run.git.commit or None,
  File "/home/lujunda/.conda/envs/myyolov5/lib/python3.7/site-packages/wandb/apis/normalize.py", line 73, in wrapper
    raise err
  File "/home/lujunda/.conda/envs/myyolov5/lib/python3.7/site-packages/wandb/apis/normalize.py", line 41, in wrapper
    return func(*args, **kwargs)
  File "/home/lujunda/.conda/envs/myyolov5/lib/python3.7/site-packages/wandb/sdk/internal/internal_api.py", line 2220, in upsert_run
    **kwargs,
  File "/home/lujunda/.conda/envs/myyolov5/lib/python3.7/site-packages/wandb/sdk/internal/internal_api.py", line 344, in gql
    **kwargs,
  File "/home/lujunda/.conda/envs/myyolov5/lib/python3.7/site-packages/wandb/sdk/lib/retry.py", line 147, in __call__
    retry_timedelta_triggered = check_retry_fn(e)
  File "/home/lujunda/.conda/envs/myyolov5/lib/python3.7/site-packages/wandb/util.py", line 968, in check_retry_fn
    return fallback_retry_fn(e)
  File "/home/lujunda/.conda/envs/myyolov5/lib/python3.7/site-packages/wandb/util.py", line 911, in no_retry_auth
    "It appears that you do not have permission to access the requested resource. "
wandb.errors.CommError: It appears that you do not have permission to access the requested resource. Please reach out to the project owner to grant you access. If you have the correct permissions, verify that there are no issues with your networking setup.(Error 404: Not Found)
2024-03-14 17:41:47,911 DEBUG   HandlerThread:175919 [handler.py:handle_request():146] handle_request: shutdown
2024-03-14 17:41:47,912 INFO    HandlerThread:175919 [handler.py:finish():869] shutting down handler
2024-03-14 17:41:48,300 INFO    WriterThread:175919 [datastore.py:close():296] close: /data/lujunda/baidu/duomo/data/leftdata/clipscore/cloth-matvh/wandb/run-20240314_174145-bk7j44wm/run-bk7j44wm.wandb
2024-03-14 17:41:48,898 INFO    SenderThread:175919 [sender.py:finish():1521] shutting down sender
